<?xml version="1.0" ?>
<!-- =================================================================================== -->
<!-- |    This document was autogenerated by xacro from fake_base.xacro                | -->
<!-- |    EDITING THIS FILE BY HAND IS NOT RECOMMENDED                                 | -->
<!-- =================================================================================== -->
<robot name="mobile_manipulator" xmlns:gz="http://gazebosim.org/schema">
  <link name="map"/>
  <link name="linear_x"/>
  <link name="linear_y"/>
  <link name="rotate_z"/>
  <link name="mount_frame"/>
  <joint name="joint_x" type="prismatic">
    <parent link="map"/>
    <child link="linear_x"/>
    <axis xyz="1 0 0"/>
    <limit effort="1000000" lower="-1000000" upper="1000000" velocity="1000000"/>
  </joint>
  <joint name="joint_y" type="prismatic">
    <parent link="linear_x"/>
    <child link="linear_y"/>
    <axis xyz="0 1 0"/>
    <limit effort="1000000" lower="-1000000" upper="1000000" velocity="1000000"/>
  </joint>
  <joint name="joint_rz" type="continuous">
    <parent link="linear_y"/>
    <child link="rotate_z"/>
    <axis xyz="0 0 1"/>
    <limit effort="1000000" velocity="1000000"/>
  </joint>
  <joint name="to_mount_frame" type="fixed">
    <parent link="rotate_z"/>
    <child link="mount_frame"/>
  </joint>
  <ros2_control name="fake_base" type="system">
    <hardware>
      <plugin>mock_components/GenericSystem</plugin>
    </hardware>
    <joint name="joint_x">
      <command_interface name="position"/>
      <command_interface name="velocity"/>
      <state_interface name="position"/>
      <state_interface name="velocity"/>
    </joint>
    <joint name="joint_y">
      <command_interface name="position"/>
      <command_interface name="velocity"/>
      <state_interface name="position"/>
      <state_interface name="velocity"/>
    </joint>
    <joint name="joint_rz">
      <command_interface name="position"/>
      <command_interface name="velocity"/>
      <state_interface name="position"/>
      <state_interface name="velocity"/>
    </joint>
  </ros2_control>
</robot>
